Workbook
Name \P: '[1]JULY-06'!#REF!
Name \P: '[1]JULY-06'!#REF!
Name \P: '[1]JULY-06'!#REF!
Name \P: '[1]JULY-06'!#REF!
Name \P: '[1]JULY-06'!#REF!
Name _: '[2]P&L, CF and Notes'!#REF!
Name _: '[2]P&L, CF and Notes'!#REF!
Name _: '[2]P&L, CF and Notes'!#REF!
Name _: '[2]P&L, CF and Notes'!#REF!
Name _: '[2]P&L, CF and Notes'!#REF!
Name _______lkm2: #N/A
Name ______J439643: [3]Notes!#REF!
Name ______J439643: [3]Notes!#REF!
Name ______J439643: [3]Notes!#REF!
Name ______J439643: [3]Notes!#REF!
Name ______J439643: [3]Notes!#REF!
Name ______lkm2: #N/A
Name _____J439643: [3]Notes!#REF!
Name _____J439643: [3]Notes!#REF!
Name _____J439643: [3]Notes!#REF!
Name _____J439643: [3]Notes!#REF!
Name _____J439643: [3]Notes!#REF!
Name _____RSE1: #REF!
Name _____RSE1: #REF!
Name _____RSE1: #REF!
Name _____RSE1: #REF!
Name _____RSE1: #REF!
Name _____RSE2: #REF!
Name _____RSE2: #REF!
Name _____RSE2: #REF!
Name _____RSE2: #REF!
Name _____RSE2: #REF!
Name ____DEC97: [4]SPIN!$A$105:$I$106
Name ____FEB98: [4]SPIN!$A$155:$I$156
Name ____JAN98: [4]SPIN!$A$135:$I$136
Name ____lkm2: #N/A
Name ____MAR98: [4]SPIN!$A$180:$I$181
Name ____MAY98: [4]SPIN!$A$237:$I$238
Name ____NOV97: [4]SPIN!$A$73:$I$74
Name ____OCT97: [4]SPIN!$A$40:$I$41
Name ____RSE1: #REF!
Name ____RSE1: #REF!
Name ____RSE1: #REF!
Name ____RSE1: #REF!
Name ____RSE1: #REF!
Name ____RSE2: #REF!
Name ____RSE2: #REF!
Name ____RSE2: #REF!
Name ____RSE2: #REF!
Name ____RSE2: #REF!
Name ____T2: '[5]Sugar tax dep'!$L$29
Name ___DEC97: [4]SPIN!$A$105:$I$106
Name ___FEB98: [4]SPIN!$A$155:$I$156
Name ___J439643: [3]Notes!#REF!
Name ___J439643: [3]Notes!#REF!
Name ___J439643: [3]Notes!#REF!
Name ___J439643: [3]Notes!#REF!
Name ___J439643: [3]Notes!#REF!
Name ___JAN98: [4]SPIN!$A$135:$I$136
Name ___MAR98: [4]SPIN!$A$180:$I$181

Sheet Cover
G2: 1 | H2: 2 | I2: 3 | J2: 4 | K2: 5 | L2: 6 | M2: 7 | N2: 8 | O2: 9 | P2: 10 | Q2: 11
C3: 12 | I3: Months | J3: Current | K3: Last Year | M3: Cummulative Months | N3: Days | O3: Cumm | P3: Heading | Q3: Budget
G4: 1 | I4: Current Month - January | J4: =+SOMCI!F$9 -> 45474 | K4: 42005 | L4: 12/11 | M4: Cumulative 1 Months ended January | N4: 31 | O4: =N4 -> 31 | P4: =TEXT(J4,"mmmm-yyyy") -> July-2024
G5: 2 | I5: Current Month - February | J5: =+SOMCI!G$9 -> 45505 | K5: 42036 | L5: 12/11 | M5: Cumulative 2 Months ended February | N5: 28 | O5: =O4+N5 -> 59 | P5: =TEXT(J5,"mmmm-yyyy") -> August-2024 | Q5: 2016
G6: 3 | I6: Current Month - March | J6: =+SOMCI!H$9 -> 45536 | K6: 42064 | L6: 12/11 | M6: Cumulative 3 Months ended March | N6: 31 | O6: =O5+N6 -> 90 | P6: =TEXT(J6,"mmmm-yyyy") -> September-2024 | Q6: 2016
A7: ="Report Period " &TEXT(VLOOKUP($C$3,Date_data,4,),"MMMM - YYYY") -> Report Period June - 2025 | G7: 4 | I7: Current Month - April | J7: =+SOMCI!I$9 -> 45566 | K7: 42095 | L7: 12/11 | M7: Cumulative 4 Months ended April | N7: 30 | O7: =O6+N7 -> 120 | P7: =TEXT(J7,"mmmm-yyyy") -> October-2024 | Q7: 2016
G8: 5 | I8: Current Month - May | J8: =+SOMCI!J$9 -> 45597 | K8: 42125 | L8: 12/11 | M8: Cumulative 5 Months ended May | N8: 31 | O8: =O7+N8 -> 151 | P8: =TEXT(J8,"mmmm-yyyy") -> November-2024 | Q8: 2016
G11: 6 | I11: Current Month - June | J11: =+SOMCI!K$9 -> 45627 | K11: 42156 | L11: 12/11 | M11: Cumulative 6 Months ended June | N11: 30 | O11: =O8+N11 -> 181 | P11: =TEXT(J11,"mmmm-yyyy") -> December-2024 | Q11: 2016
A12: Western Vending Machines LLC | G12: 7 | I12: Current Month - July | J12: =+SOMCI!L$9 -> 45658 | K12: 42186 | L12: 12/11 | M12: Cumulative 7 Months ended July | N12: 31 | O12: =O11+N12 -> 212 | P12: =TEXT(J12,"mmmm-yyyy") -> January-2025 | Q12: 2016
A13: DUABI UAE | G13: 8 | I13: Current Month - August | J13: =+SOMCI!M$9 -> 45689 | K13: 42217 | L13: 12/11 | M13: Cumulative 8 Months ended August | N13: 31 | O13: =O12+N13 -> 243 | P13: =TEXT(J13,"mmmm-yyyy") -> February-2025 | Q13: 2016
G14: 9 | I14: Current Month - September | J14: =+SOMCI!N$9 -> 45717 | K14: 42248 | L14: 12/11 | M14: Cumulative 9 Months ended September | N14: 30 | O14: =O13+N14 -> 273 | P14: =TEXT(J14,"mmmm-yyyy") -> March-2025 | Q14: 2016
G15: 10 | I15: Current Month - October | J15: =+SOMCI!O$9 -> 45748 | K15: 42278 | L15: 12/11 | M15: Cumulative 10 Months ended October | N15: 31 | O15: =O14+N15 -> 304 | P15: =TEXT(J15,"mmmm-yyyy") -> April-2025 | Q15: 2016
G16: 11 | I16: Current Month - November | J16: =+SOMCI!P$9 -> 45778 | K16: 42309 | L16: 12/11 | M16: Cumulative 11 Months ended November | N16: 30 | O16: =O15+N16 -> 334 | P16: =TEXT(J16,"mmmm-yyyy") -> May-2025 | Q16: 2016
G17: 12 | I17: Current Month - December | J17: =+SOMCI!Q$9 -> 45809 | K17: 42339 | L17: 12/11 | M17: Cumulative 12 Months ended December | N17: 31 | O17: =O16+N17 -> 365 | P17: =TEXT(J17,"mmmm-yyyy") -> June-2025 | Q17: 2016

Sheet Contents
A2: Bin Ghannam Accounting & Auditing
A3: Dubai, U.A.E
A4: URL:www.binghannam.com E- info@binghannam.com Tel.:971 4 2983118
A6: =Cover!A12 -> Western Vending Machines LLC
A7: =Cover!A13 -> DUABI UAE
A9: ="MIS Report Period " &TEXT(VLOOKUP(Cover!$C$3,Date_data,4,),"MMMM - YYYY") -> MIS Report Period June - 2025
A11: Table of Contents
B13: Contents | E13: Page#
B15: Galance | E15: =SUM(SUBTOTAL(103,$B$15:B15)+2) -> 3
B16: Observations & Recommendations | E16: =SUM(SUBTOTAL(103,$B$15:B16)+2) -> 4
B17: Key Performance Indicator - Comparison | E17: =SUM(SUBTOTAL(103,$B$15:B17)+2) -> 5
B18: Credit Card Machine Monthly | E18: =SUM(SUBTOTAL(103,$B$15:B18)+2) -> 6
B19: Statement of Financial Position - Balance Sheet | E19: =SUM(SUBTOTAL(103,$B$15:B19)+2) -> 7
B20: Statement of Financial Position or Balance Sheet - Monthly | E20: =SUM(SUBTOTAL(103,$B$15:B20)+2) -> 8
B21: Statement of Comprehensive Income - Profit & Loss | E21: =SUM(SUBTOTAL(103,$B$15:B21)+2) -> 9
B22: Statement of Comprehensive Income or Profit & Loss Monthly | E22: =SUM(SUBTOTAL(103,$B$15:B22)+2) -> 10
B23: Statement of Cash Flow | E23: =SUM(SUBTOTAL(103,$B$15:B23)+2) -> 10
B24: Budget Variance Statement | E24: =SUM(SUBTOTAL(103,$B$15:B24)+2) -> 10
B25: Debitors Aging Summary | E25: =SUM(SUBTOTAL(103,$B$15:B25)+2) -> 10
B26: Bank & Cash Position / Reconciliation | E26: =SUM(SUBTOTAL(103,$B$15:B26)+2) -> 10

Sheet Observations & Recommendations 
A3: =Cover!$A$12 -> Western Vending Machines LLC
A4: =Cover!$A$13 -> DUABI UAE
A5: Observations & Recommendations
A8: SR# | B8: Head | C8: Details | D8: Risk | E8: Recommendations | F8: Status
A9: 1 | B9: Cash in Machines | C9: As we didn't count physicaly cash in Machines since long | D9: There is risk of low balance of cash in Machines as we are not counting | E9: We should immediately make the arrangements to count the cash in Machines | F9: Pending
A10: 2 | B10: Revenue Overall Decrease | C10: Right Now In October-24 Revneue increase (little decrease as compare to September-24) because of Credit card machines however onverall Reveneu decreased because we lost some locations Like Al Kuwati Hospital Sharjah, Abdullah Imran Hospital Ras al khaimah, Fujerah Hospital Coffee machines, Saqar Hospital RAK | D10: The overall revenue decrease due to the loss of key hospital locations such as Al Kuwaiti Hospital Sharjah, Abdullah Imran Hospital Ras Al Khaimah, Fujairah Hospital Coffee Machines, and Saqar Hospital RAK poses a significant from One of our competitor, Dallmayr has taken over these location so there is risk that this competitor can take further locations. If more locations are lost, it could further erode the revenue base, impacting profitability and long-term operations | E10: To mitigate the revenue loss, the company should focus on securing new locations to replace those that were lost. Additionally, developing stronger partnerships with existing clients or expanding services can help increase revenue. | F10: Closed
A11: 3 | B11: Credit Card Machines Charges | C11: Credit Card Machines provider sending money to our Bank account after some deductions(Services Charges) | D11: Credit Card Machines provider may be deducting some hiden charges | E11: Please provide us with the contract details for the credit card machines. Based on the agreed percentage, we will review and calculate each transaction to ensure that the deductions reflect the correct percentage as per the agreement. | F11: Pending
A12: 4 | B12: Inventory | C12: There is no count of stock in machines available | D12: Because of not Conducting any machines stock count there is no exact inventory amount in machines is available | E12: To ensure inventory accuracy, it is advisable to conduct a comprehensive inventory count on a quarterly basis, encompassing both physical store locations and Stock in machines. | F12: Pending
A13: 5 | B13: Product Price | C13: Prices of our Products are less as compare to market | D13: We are selling at less prices and due less profit margin we are still in loss | E13: Review the products prices list and increase the prices accordingly
A14: 6 | B14: Utilities Expense | C14: Utilities and Mobile bills / expense are not paid in the month of December 2024. | D14: Its will effect on next month (January 2025) profit decrees and showing double expense | E14: Please record expenses in the same month when the expenses are incurred. | F14: Comply
A15: 7 | B15: Utilities Expense | C15: Utilities and Mobile bills are not paid on monthly basis | D15: If we are not paying on the same month when the expense are incurred. its effect on both month financials which is the wrong practice. | E15: We recommend that you make regular payments, especially when the expense occurred in the same month. | F15: Pending
A16: 8 | B16: Bank Charges / VAT | C16: Bank released to Transguard SCDMs quarterly payments via bank for two quarters with 5% VAT. | D16: You are not claiming your input VAT and this reduces your profit margin. | E16: We need to charge input VAT in our VAT return, we need to book the bills / Invoices as per the contract and pay through bill payment.
A17: 9 | B17: Vehicle Registration Charges | C17: Vehicle Registration Charges booked expesne and charges in one month. | D17: Its reduce the the profit of the month when we are making the expense. | E17: We need to charge on monthly basis because vehicle registration charges for yearly, we need to book as prepaid expense.

Sheet Galance
A2: =Cover!A12 -> Western Vending Machines LLC
A3: =Cover!A13 -> DUABI UAE
B5: Galance Picture
B7: Balance Sheet Statement 6 Month Comparison | D7: ="As On "&TEXT(SOCI!$F$8,"MMMM - YYYY") -> As On June - 2025
B9: Particulars | C9: =VLOOKUP(Cover!$C$3,Cover!$G$4:$Q$17,4,) -> 45809 | D9: =DATE(YEAR(C9),MONTH(C9)-1,1) -> 45778 | E9: =DATE(YEAR(D9),MONTH(D9)-1,1) -> 45748 | F9: =DATE(YEAR(E9),MONTH(E9)-1,1) -> 45717 | G9: =DATE(YEAR(F9),MONTH(F9)-1,1) -> 45689 | H9: =DATE(YEAR(G9),MONTH(G9)-1,1) -> 45658
B11: ASSETS: | C11: =SUM(C12:C13) -> 1008592.1 | D11: =SUM(D12:D13) -> 1017229.6 | E11: =SUM(E12:E13) -> 1037261.8 | F11: =SUM(F12:F13) -> 1038541.5 | G11: =SUM(G12:G13) -> 1081269.1 | H11: =SUM(H12:H13) -> 1031307.2
B12: Fixed Assets | C12: =_xlfn.IFNA(INDEX(SOMFP!$E$10:$P$48,MATCH(Galance!$B12,SOMFP!$A$10:$A$48,0),MATCH(Galance!C$9,SOMFP!$E$8:$P$8,0)),0) -> 622270.55 | D12: =_xlfn.IFNA(INDEX(SOMFP!$E$10:$P$48,MATCH(Galance!$B12,SOMFP!$A$10:$A$48,0),MATCH(Galance!D$9,SOMFP!$E$8:$P$8,0)),0) -> 622270.55 | E12: =_xlfn.IFNA(INDEX(SOMFP!$E$10:$P$48,MATCH(Galance!$B12,SOMFP!$A$10:$A$48,0),MATCH(Galance!E$9,SOMFP!$E$8:$P$8,0)),0) -> 626420.55 | F12: =_xlfn.IFNA(INDEX(SOMFP!$E$10:$P$48,MATCH(Galance!$B12,SOMFP!$A$10:$A$48,0),MATCH(Galance!F$9,SOMFP!$E$8:$P$8,0)),0) -> 627520.55 | G12: =_xlfn.IFNA(INDEX(SOMFP!$E$10:$P$48,MATCH(Galance!$B12,SOMFP!$A$10:$A$48,0),MATCH(Galance!G$9,SOMFP!$E$8:$P$8,0)),0) -> 621690.55 | H12: =_xlfn.IFNA(INDEX(SOMFP!$E$10:$P$48,MATCH(Galance!$B12,SOMFP!$A$10:$A$48,0),MATCH(Galance!H$9,SOMFP!$E$8:$P$8,0)),0) -> 622790.55
B13: Current Assets | C13: =INDEX(SOMFP!$E$10:$P$48,MATCH(Galance!$B13,SOMFP!$A$10:$A$48,0),MATCH(Galance!C$9,SOMFP!$E$8:$P$8,0)) -> 386321.55 | D13: =INDEX(SOMFP!$E$10:$P$48,MATCH(Galance!$B13,SOMFP!$A$10:$A$48,0),MATCH(Galance!D$9,SOMFP!$E$8:$P$8,0)) -> 394959 | E13: =INDEX(SOMFP!$E$10:$P$48,MATCH(Galance!$B13,SOMFP!$A$10:$A$48,0),MATCH(Galance!E$9,SOMFP!$E$8:$P$8,0)) -> 410841.2 | F13: =INDEX(SOMFP!$E$10:$P$48,MATCH(Galance!$B13,SOMFP!$A$10:$A$48,0),MATCH(Galance!F$9,SOMFP!$E$8:$P$8,0)) -> 411020.9 | G13: =INDEX(SOMFP!$E$10:$P$48,MATCH(Galance!$B13,SOMFP!$A$10:$A$48,0),MATCH(Galance!G$9,SOMFP!$E$8:$P$8,0)) -> 459578.57 | H13: =INDEX(SOMFP!$E$10:$P$48,MATCH(Galance!$B13,SOMFP!$A$10:$A$48,0),MATCH(Galance!H$9,SOMFP!$E$8:$P$8,0)) -> 408516.63
B15: LIABILITIES: | C15: =SUM(C16:C17) -> -1886579.9 | D15: =SUM(D16:D17) -> -1822545.7 | E15: =SUM(E16:E17) -> -1767570.8 | F15: =SUM(F16:F17) -> -1718426.7 | G15: =SUM(G16:G17) -> -1683611.1 | H15: =SUM(H16:H17) -> -1603018.1
B16: Non-current Liabilities | C16: =-INDEX(SOMFP!$E$10:$P$48,MATCH(Galance!$B16,SOMFP!$A$10:$A$48,0),MATCH(Galance!C$9,SOMFP!$E$8:$P$8,0)) -> 0 | D16: =-INDEX(SOMFP!$E$10:$P$48,MATCH(Galance!$B16,SOMFP!$A$10:$A$48,0),MATCH(Galance!D$9,SOMFP!$E$8:$P$8,0)) -> 0 | E16: =-INDEX(SOMFP!$E$10:$P$48,MATCH(Galance!$B16,SOMFP!$A$10:$A$48,0),MATCH(Galance!E$9,SOMFP!$E$8:$P$8,0)) -> -2584 | F16: =-INDEX(SOMFP!$E$10:$P$48,MATCH(Galance!$B16,SOMFP!$A$10:$A$48,0),MATCH(Galance!F$9,SOMFP!$E$8:$P$8,0)) -> -5168 | G16: =-INDEX(SOMFP!$E$10:$P$48,MATCH(Galance!$B16,SOMFP!$A$10:$A$48,0),MATCH(Galance!G$9,SOMFP!$E$8:$P$8,0)) -> -7752 | H16: =-INDEX(SOMFP!$E$10:$P$48,MATCH(Galance!$B16,SOMFP!$A$10:$A$48,0),MATCH(Galance!H$9,SOMFP!$E$8:$P$8,0)) -> -10336
B17: Current liabilities | C17: =-INDEX(SOMFP!$E$10:$P$48,MATCH(Galance!$B17,SOMFP!$A$10:$A$48,0),MATCH(Galance!C$9,SOMFP!$E$8:$P$8,0)) -> -1886579.9 | D17: =-INDEX(SOMFP!$E$10:$P$48,MATCH(Galance!$B17,SOMFP!$A$10:$A$48,0),MATCH(Galance!D$9,SOMFP!$E$8:$P$8,0)) -> -1822545.7 | E17: =-INDEX(SOMFP!$E$10:$P$48,MATCH(Galance!$B17,SOMFP!$A$10:$A$48,0),MATCH(Galance!E$9,SOMFP!$E$8:$P$8,0)) -> -1764986.8 | F17: =-INDEX(SOMFP!$E$10:$P$48,MATCH(Galance!$B17,SOMFP!$A$10:$A$48,0),MATCH(Galance!F$9,SOMFP!$E$8:$P$8,0)) -> -1713258.7 | G17: =-INDEX(SOMFP!$E$10:$P$48,MATCH(Galance!$B17,SOMFP!$A$10:$A$48,0),MATCH(Galance!G$9,SOMFP!$E$8:$P$8,0)) -> -1675859.1 | H17: =-INDEX(SOMFP!$E$10:$P$48,MATCH(Galance!$B17,SOMFP!$A$10:$A$48,0),MATCH(Galance!H$9,SOMFP!$E$8:$P$8,0)) -> -1592682.1
B18: Net worth | C18: =+C11+C15 -> -877987.75 | D18: =+D11+D15 -> -805316.17 | E18: =+E11+E15 -> -730309.02 | F18: =+F11+F15 -> -679885.22 | G18: =+G11+G15 -> -602342.01 | H18: =+H11+H15 -> -571710.96
B20: Profit & Loss Statement 6 Month Comparison | D20: ="For the month of "&TEXT(SOCI!$F$8,"MMMM - YYYY") -> For the month of June - 2025
B22: Particulars | C22: =VLOOKUP(Cover!$C$3,Cover!$G$4:$Q$17,4,) -> 45809 | D22: =DATE(YEAR(C22),MONTH(C22)-1,1) -> 45778 | E22: =DATE(YEAR(D22),MONTH(D22)-1,1) -> 45748 | F22: =DATE(YEAR(E22),MONTH(E22)-1,1) -> 45717 | G22: =DATE(YEAR(F22),MONTH(F22)-1,1) -> 45689 | H22: =DATE(YEAR(G22),MONTH(G22)-1,1) -> 45658
B24: Revenue | C24: =INDEX(SOMCI!$F$11:$R$67,MATCH(Galance!$B24,SOMCI!$A$11:$A$67,0),MATCH(Galance!C$22,SOMCI!$F$9:$Q$9,0)) -> 67980.55 | D24: =INDEX(SOMCI!$F$11:$R$67,MATCH(Galance!$B24,SOMCI!$A$11:$A$67,0),MATCH(Galance!D$22,SOMCI!$F$9:$Q$9,0)) -> 87520.02 | E24: =INDEX(SOMCI!$F$11:$R$67,MATCH(Galance!$B24,SOMCI!$A$11:$A$67,0),MATCH(Galance!E$22,SOMCI!$F$9:$Q$9,0)) -> 87876.29 | F24: =INDEX(SOMCI!$F$11:$R$67,MATCH(Galance!$B24,SOMCI!$A$11:$A$67,0),MATCH(Galance!F$22,SOMCI!$F$9:$Q$9,0)) -> 61941.45 | G24: =INDEX(SOMCI!$F$11:$R$67,MATCH(Galance!$B24,SOMCI!$A$11:$A$67,0),MATCH(Galance!G$22,SOMCI!$F$9:$Q$9,0)) -> 111884.84 | H24: =INDEX(SOMCI!$F$11:$R$67,MATCH(Galance!$B24,SOMCI!$A$11:$A$67,0),MATCH(Galance!G$22,SOMCI!$H$9:$Q$9,0)) -> 119041.63
B25: Direct Expenses | C25: =INDEX(SOMCI!$F$11:$R$67,MATCH(Galance!$B25,SOMCI!$A$11:$A$67,0),MATCH(Galance!C$22,SOMCI!$F$9:$Q$9,0)) -> 38352.35 | D25: =INDEX(SOMCI!$F$11:$R$67,MATCH(Galance!$B25,SOMCI!$A$11:$A$67,0),MATCH(Galance!D$22,SOMCI!$F$9:$Q$9,0)) -> 42536.15 | E25: =INDEX(SOMCI!$F$11:$R$67,MATCH(Galance!$B25,SOMCI!$A$11:$A$67,0),MATCH(Galance!E$22,SOMCI!$F$9:$Q$9,0)) -> 53057.19 | F25: =INDEX(SOMCI!$F$11:$R$67,MATCH(Galance!$B25,SOMCI!$A$11:$A$67,0),MATCH(Galance!F$22,SOMCI!$F$9:$Q$9,0)) -> 22914.83 | G25: =INDEX(SOMCI!$F$11:$R$67,MATCH(Galance!$B25,SOMCI!$A$11:$A$67,0),MATCH(Galance!G$22,SOMCI!$F$9:$Q$9,0)) -> 57339.56 | H25: =INDEX(SOMCI!$F$11:$R$67,MATCH(Galance!$B25,SOMCI!$A$11:$A$67,0),MATCH(Galance!H$22,SOMCI!$F$9:$Q$9,0)) -> 60816.33
B26: Gross Profit / (Loss) | C26: =INDEX(SOMCI!$F$11:$R$67,MATCH(Galance!$B26,SOMCI!$A$11:$A$67,0),MATCH(Galance!C$22,SOMCI!$F$9:$Q$9,0)) -> 29628.2 | D26: =+D24-D25 -> 44983.87 | E26: =+E24-E25 -> 34819.1 | F26: =+F24-F25 -> 39026.62 | G26: =+G24-G25 -> 54545.28 | H26: =+H24-H25 -> 58225.3
B27: Indirect Expenses | C27: =INDEX(SOMCI!$F$11:$R$67,MATCH(Galance!$B27,SOMCI!$A$11:$A$67,0),MATCH(Galance!C$22,SOMCI!$F$9:$Q$9,0)) -> 103004.37 | D27: =INDEX(SOMCI!$F$11:$R$67,MATCH(Galance!$B27,SOMCI!$A$11:$A$67,0),MATCH(Galance!D$22,SOMCI!$F$9:$Q$9,0)) -> 118541.28 | E27: =INDEX(SOMCI!$F$11:$R$67,MATCH(Galance!$B27,SOMCI!$A$11:$A$67,0),MATCH(Galance!E$22,SOMCI!$F$9:$Q$9,0)) -> 84142.9 | F27: =INDEX(SOMCI!$F$11:$R$67,MATCH(Galance!$B27,SOMCI!$A$11:$A$67,0),MATCH(Galance!F$22,SOMCI!$F$9:$Q$9,0)) -> 116857.08 | G27: =INDEX(SOMCI!$F$11:$R$67,MATCH(Galance!$B27,SOMCI!$A$11:$A$67,0),MATCH(Galance!G$22,SOMCI!$F$9:$Q$9,0)) -> 88613.98 | H27: =INDEX(SOMCI!$F$11:$R$67,MATCH(Galance!$B27,SOMCI!$A$11:$A$67,0),MATCH(Galance!H$22,SOMCI!$F$9:$Q$9,0)) -> 147096.5
B28: Net Profit / (Loss) | C28: =INDEX(SOMCI!$F$11:$R$67,MATCH(Galance!$B28,SOMCI!$A$11:$A$67,0),MATCH(Galance!C$22,SOMCI!$F$9:$Q$9,0)) -> -73376.17 | D28: =+D26-D27 -> -73557.41 | E28: =+E26-E27 -> -49323.8 | F28: =+F26-F27 -> -77830.46 | G28: =+G26-G27 -> -34068.7 | H28: =+H26-H27 -> -88871.2

Sheet KPI Comparisons
A2: =Cover!A12 -> Western Vending Machines LLC
A3: =Cover!A13 -> DUABI UAE
A5: Key Performance Indicator - Comparison

Sheet Credit Card Machines
A2: =SOFP!A2 -> Western Vending Machines LLC
A3: =SOFP!A3 -> DUABI UAE
A6: Nayax Credit Card Sales report
A7: Report Type | B7: Nayax Credit Card sale | C7: Total deposit In bank
A8: 45474 | B8: 30290 | C8: 29713.22
A9: =DATE(YEAR(A8),MONTH(A8)+1,1) -> 45505 | B9: 37682 | C9: 36071.72
A10: =DATE(YEAR(A9),MONTH(A9)+1,1) -> 45536 | B10: 45466 | C10: 43446.32
A11: =DATE(YEAR(A10),MONTH(A10)+1,1) -> 45566 | B11: 50058 | C11: 49201.24
A12: =DATE(YEAR(A11),MONTH(A11)+1,1) -> 45597 | B12: 47365 | C12: 46241.28
A13: =DATE(YEAR(A12),MONTH(A12)+1,1) -> 45627 | B13: 43694.9 | C13: 42451.7
A14: =DATE(YEAR(A13),MONTH(A13)+1,1) -> 45658 | B14: 43302 | C14: 40328.88
A15: =DATE(YEAR(A14),MONTH(A14)+1,1) -> 45689 | B15: 44036 | C15: 40781.87
A16: =DATE(YEAR(A15),MONTH(A15)+1,1) -> 45717 | B16: 28948 | C16: 25440.3
A17: =DATE(YEAR(A16),MONTH(A16)+1,1) -> 45748 | B17: 37943 | C17: 35515.85
A18: =DATE(YEAR(A17),MONTH(A17)+1,1) -> 45778 | B18: 37640 | C18: 35142.02
A19: =DATE(YEAR(A18),MONTH(A18)+1,1) -> 45809 | B19: 31455 | C19: ='Linked IS'!D7*105/100 -> 27610.58
A20: Total | B20: =SUM(B8:B19) -> 477879.9 | C20: =SUM(C8:C19) -> 451944.98
A22: Difference/Nayax Charges | C22: =B20-C20 -> 25934.921

Sheet SOFP
A2: =Cover!A12 -> Western Vending Machines LLC
A3: =Cover!A13 -> DUABI UAE
A5: STATEMENT OF FINANCIAL POSITION
A6: =Galance!D7 -> As On June - 2025
A7: Amount in AED
A8: Particulars | C8: Note | E8: =+SOCI!F8 -> 45809 | G8: =+SOCI!H8 -> 45778 | H8: =DATE(YEAR(G8),MONTH(G8)-1,1) -> 45748
A9: Assets:
A10: Fixed Assets | E10: =SUM(E11:E13) -> 622270.55 | G10: =SUM(G11:G13) -> 622270.55 | H10: =SUM(H11:H13) -> 626420.55
E11: =IFERROR(INDEX(SOMFP!$E$11:$P$48,MATCH($B11,SOMFP!$B$11:$B$43,0),MATCH($E$8,SOMFP!$E$8:$P$8,0)),"") | G11: =IFERROR(INDEX(SOMFP!$E$11:$P$48,MATCH($B11,SOMFP!$B$11:$B$43,0),MATCH($G$8,SOMFP!$E$8:$P$8,0)),"") | H11: =IFERROR(INDEX(SOMFP!$E$11:$P$48,MATCH($B11,SOMFP!$B$11:$B$43,0),MATCH($H$8,SOMFP!$E$8:$P$8,0)),"")
B12: =SOMFP!B12 -> Property and equipement | E12: =IFERROR(INDEX(SOMFP!$E$11:$P$48,MATCH($B12,SOMFP!$B$11:$B$43,0),MATCH($E$8,SOMFP!$E$8:$P$8,0)),"") -> 622270.55 | G12: =IFERROR(INDEX(SOMFP!$E$11:$P$48,MATCH($B12,SOMFP!$B$11:$B$43,0),MATCH($G$8,SOMFP!$E$8:$P$8,0)),"") -> 622270.55 | H12: =IFERROR(INDEX(SOMFP!$E$11:$P$48,MATCH($B12,SOMFP!$B$11:$B$43,0),MATCH($H$8,SOMFP!$E$8:$P$8,0)),"") -> 626420.55
E13: =IFERROR(INDEX(SOMFP!$E13:$P$48,MATCH($B$11,SOMFP!$B$11:$B$43,0),MATCH($E$8,SOMFP!$E$8:$P$8,0)),"") | G13: =IFERROR(INDEX(SOMFP!$E$11:$P$48,MATCH($B13,SOMFP!$B$11:$B$43,0),MATCH($G$8,SOMFP!$E$8:$P$8,0)),"") | H13: =IFERROR(INDEX(SOMFP!$E$11:$P$48,MATCH($B13,SOMFP!$B$11:$B$43,0),MATCH($H$8,SOMFP!$E$8:$P$8,0)),"")
A15: Current Assets | E15: =SUM(E16:E25) -> 386321.55 | G15: =SUM(G16:G25) -> 394959 | H15: =SUM(H16:H25) -> 200492.64
B16: ADIB | E16: =IFERROR(INDEX(SOMFP!$E$11:$P$48,MATCH($B16,SOMFP!$B$11:$B$43,0),MATCH($E$8,SOMFP!$E$8:$P$8,0)),"") -> 2948.1 | G16: =IFERROR(INDEX(SOMFP!$E$11:$P$48,MATCH($B16,SOMFP!$B$11:$B$43,0),MATCH($G$8,SOMFP!$E$8:$P$8,0)),"") -> 20188.56 | H16: =IFERROR(INDEX(SOMFP!$E$11:$P$48,MATCH($B16,SOMFP!$B$11:$B$43,0),MATCH($H$8,SOMFP!$E$8:$P$8,0)),"") -> 17866.73
B17: Ajman Petty-Cash | E17: =IFERROR(INDEX(SOMFP!$E$11:$P$48,MATCH($B17,SOMFP!$B$11:$B$43,0),MATCH($E$8,SOMFP!$E$8:$P$8,0)),"") -> -62.1 | G17: =IFERROR(INDEX(SOMFP!$E$11:$P$48,MATCH($B17,SOMFP!$B$11:$B$43,0),MATCH($G$8,SOMFP!$E$8:$P$8,0)),"") -> -62.1 | H17: =IFERROR(INDEX(SOMFP!$E$11:$P$48,MATCH($B17,SOMFP!$B$11:$B$43,0),MATCH($H$8,SOMFP!$E$8:$P$8,0)),"") -> -62.1
B18: Main Cash (Collection) | E18: =IFERROR(INDEX(SOMFP!$E$11:$P$48,MATCH($B18,SOMFP!$B$11:$B$43,0),MATCH($E$8,SOMFP!$E$8:$P$8,0)),"") -> 6684.34 | G18: =IFERROR(INDEX(SOMFP!$E$11:$P$48,MATCH($B18,SOMFP!$B$11:$B$43,0),MATCH($G$8,SOMFP!$E$8:$P$8,0)),"") -> 5345.34
B19: Advance to employee | E19: =IFERROR(INDEX(SOMFP!$E$11:$P$48,MATCH($B19,SOMFP!$B$11:$B$43,0),MATCH($E$8,SOMFP!$E$8:$P$8,0)),"") -> 109206.5 | G19: =IFERROR(INDEX(SOMFP!$E$11:$P$48,MATCH($B19,SOMFP!$B$11:$B$43,0),MATCH($G$8,SOMFP!$E$8:$P$8,0)),"") -> 109206.5
B20: Cash in Machines | E20: =IFERROR(INDEX(SOMFP!$E$11:$P$48,MATCH($B20,SOMFP!$B$11:$B$43,0),MATCH($E$8,SOMFP!$E$8:$P$8,0)),"") -> 49326 | G20: =IFERROR(INDEX(SOMFP!$E$11:$P$48,MATCH($B20,SOMFP!$B$11:$B$43,0),MATCH($G$8,SOMFP!$E$8:$P$8,0)),"") -> 50331 | H20: =IFERROR(INDEX(SOMFP!$E$11:$P$48,MATCH($B20,SOMFP!$B$11:$B$43,0),MATCH($H$8,SOMFP!$E$8:$P$8,0)),"") -> 50331
B21: Fuel Adnoc balance | E21: =IFERROR(INDEX(SOMFP!$E$11:$P$48,MATCH($B21,SOMFP!$B$11:$B$43,0),MATCH($E$8,SOMFP!$E$8:$P$8,0)),"") -> 1645.4 | G21: =IFERROR(INDEX(SOMFP!$E$11:$P$48,MATCH($B21,SOMFP!$B$11:$B$43,0),MATCH($G$8,SOMFP!$E$8:$P$8,0)),"") -> 1288.4
B22: Inventory | E22: =IFERROR(INDEX(SOMFP!$E$11:$P$48,MATCH($B22,SOMFP!$B$11:$B$43,0),MATCH($E$8,SOMFP!$E$8:$P$8,0)),"") -> 86361.36 | G22: =IFERROR(INDEX(SOMFP!$E$11:$P$48,MATCH($B22,SOMFP!$B$11:$B$43,0),MATCH($G$8,SOMFP!$E$8:$P$8,0)),"") -> 83871.71
B23: Prepayments | E23: =IFERROR(INDEX(SOMFP!$E$11:$P$48,MATCH($B23,SOMFP!$B$11:$B$43,0),MATCH($E$8,SOMFP!$E$8:$P$8,0)),"") -> 66258.67 | G23: =IFERROR(INDEX(SOMFP!$E$11:$P$48,MATCH($B23,SOMFP!$B$11:$B$43,0),MATCH($G$8,SOMFP!$E$8:$P$8,0)),"") -> 60836.31 | H23: =IFERROR(INDEX(SOMFP!$E$11:$P$48,MATCH($B23,SOMFP!$B$11:$B$43,0),MATCH($H$8,SOMFP!$E$8:$P$8,0)),"") -> 69053.73
B24: Accounts receivable | E24: =IFERROR(INDEX(SOMFP!$E$11:$P$48,MATCH($B24,SOMFP!$B$11:$B$43,0),MATCH($E$8,SOMFP!$E$8:$P$8,0)),"") -> 27243.28 | G24: =IFERROR(INDEX(SOMFP!$E$11:$P$48,MATCH($B24,SOMFP!$B$11:$B$43,0),MATCH($G$8,SOMFP!$E$8:$P$8,0)),"") -> 27243.28 | H24: =IFERROR(INDEX(SOMFP!$E$11:$P$48,MATCH($B24,SOMFP!$B$11:$B$43,0),MATCH($H$8,SOMFP!$E$8:$P$8,0)),"") -> 27243.28
B25: Securities | E25: =IFERROR(INDEX(SOMFP!$E$11:$P$48,MATCH($B25,SOMFP!$B$11:$B$43,0),MATCH($E$8,SOMFP!$E$8:$P$8,0)),"") -> 36710 | G25: =IFERROR(INDEX(SOMFP!$E$11:$P$48,MATCH($B25,SOMFP!$B$11:$B$43,0),MATCH($G$8,SOMFP!$E$8:$P$8,0)),"") -> 36710 | H25: =IFERROR(INDEX(SOMFP!$E$11:$P$48,MATCH($B25,SOMFP!$B$11:$B$43,0),MATCH($H$8,SOMFP!$E$8:$P$8,0)),"") -> 36060
A27: Total Assets | E27: =+E10+E15 -> 1008592.1 | G27: =+G10+G15 -> 1017229.6 | H27: =+H10+#REF!+H15 -> #REF!
A29: Equity & Liabilities:
A30: Equity | E30: =SUM(E31:E35) -> -877987.75 | G30: =SUM(G31:G35) -> -805316.17 | H30: =SUM(H31:H35) -> -730309.02
B31: =SOMFP!B29 -> Net Income | E31: =IFERROR(INDEX(SOMFP!$E$11:$P$48,MATCH($B31,SOMFP!$B$11:$B$43,0),MATCH($E$8,SOMFP!$E$8:$P$8,0)),"") -> -408700.65 | G31: =IFERROR(INDEX(SOMFP!$E$11:$P$48,MATCH($B31,SOMFP!$B$11:$B$43,0),MATCH($G$8,SOMFP!$E$8:$P$8,0)),"") -> -336029.07 | H31: =IFERROR(INDEX(SOMFP!$E$11:$P$48,MATCH($B31,SOMFP!$B$11:$B$43,0),MATCH($H$8,SOMFP!$E$8:$P$8,0)),"") -> -261021.92
B32: =SOMFP!B30 -> Drawings | E32: =IFERROR(INDEX(SOMFP!$E$11:$P$48,MATCH($B32,SOMFP!$B$11:$B$43,0),MATCH($E$8,SOMFP!$E$8:$P$8,0)),"") -> 267396.82 | G32: =IFERROR(INDEX(SOMFP!$E$11:$P$48,MATCH($B32,SOMFP!$B$11:$B$43,0),MATCH($G$8,SOMFP!$E$8:$P$8,0)),"") -> 267396.82 | H32: =IFERROR(INDEX(SOMFP!$E$11:$P$48,MATCH($B32,SOMFP!$B$11:$B$43,0),MATCH($H$8,SOMFP!$E$8:$P$8,0)),"") -> 267396.82
B33: =SOMFP!B31 -> Opening Balance Equity | E33: =IFERROR(INDEX(SOMFP!$E$11:$P$48,MATCH($B33,SOMFP!$B$11:$B$43,0),MATCH($E$8,SOMFP!$E$8:$P$8,0)),"") -> 352723.59 | G33: =IFERROR(INDEX(SOMFP!$E$11:$P$48,MATCH($B33,SOMFP!$B$11:$B$43,0),MATCH($G$8,SOMFP!$E$8:$P$8,0)),"") -> 352723.59 | H33: =IFERROR(INDEX(SOMFP!$E$11:$P$48,MATCH($B33,SOMFP!$B$11:$B$43,0),MATCH($H$8,SOMFP!$E$8:$P$8,0)),"") -> 352723.59
B34: =SOMFP!B32 -> Retained Earnings | E34: =IFERROR(INDEX(SOMFP!$E$11:$P$48,MATCH($B34,SOMFP!$B$11:$B$43,0),MATCH($E$8,SOMFP!$E$8:$P$8,0)),"") -> -1217361 | G34: =IFERROR(INDEX(SOMFP!$E$11:$P$48,MATCH($B34,SOMFP!$B$11:$B$43,0),MATCH($G$8,SOMFP!$E$8:$P$8,0)),"") -> -1217361 | H34: =IFERROR(INDEX(SOMFP!$E$11:$P$48,MATCH($B34,SOMFP!$B$11:$B$43,0),MATCH($H$8,SOMFP!$E$8:$P$8,0)),"") -> -1217361
B35: =SOMFP!B33 -> Share holder current account | E35: =IFERROR(INDEX(SOMFP!$E$11:$P$48,MATCH($B35,SOMFP!$B$11:$B$43,0),MATCH($E$8,SOMFP!$E$8:$P$8,0)),"") -> 127953.52 | G35: =IFERROR(INDEX(SOMFP!$E$11:$P$48,MATCH($B35,SOMFP!$B$11:$B$43,0),MATCH($G$8,SOMFP!$E$8:$P$8,0)),"") -> 127953.52 | H35: =IFERROR(INDEX(SOMFP!$E$11:$P$48,MATCH($B35,SOMFP!$B$11:$B$43,0),MATCH($H$8,SOMFP!$E$8:$P$8,0)),"") -> 127953.52
A37: Non-current Liabilities | E37: =SUM(E38:E39) -> 0 | G37: =SUM(G38:G39) -> 0 | H37: =SUM(H38:H39) -> 2584
E38: =IFERROR(INDEX(SOMFP!$E$11:$P$48,MATCH($B38,SOMFP!$B$11:$B$43,0),MATCH($E$8,SOMFP!$E$8:$P$8,0)),"") | G38: =IFERROR(INDEX(SOMFP!$E$11:$P$48,MATCH($B38,SOMFP!$B$11:$B$43,0),MATCH($G$8,SOMFP!$E$8:$P$8,0)),"") | H38: =IFERROR(INDEX(SOMFP!$E$11:$P$48,MATCH($B38,SOMFP!$B$11:$B$43,0),MATCH($H$8,SOMFP!$E$8:$P$8,0)),"")
B39: =SOMFP!B37 -> Leased Vehicle | E39: =IFERROR(INDEX(SOMFP!$E$11:$P$48,MATCH($B39,SOMFP!$B$11:$B$43,0),MATCH($E$8,SOMFP!$E$8:$P$8,0)),"") -> 0 | G39: =IFERROR(INDEX(SOMFP!$E$11:$P$48,MATCH($B39,SOMFP!$B$11:$B$48,0),MATCH($G$8,SOMFP!$E$8:$P$8,0)),"") -> 0 | H39: =IFERROR(INDEX(SOMFP!$E$11:$P$48,MATCH($B39,SOMFP!$B$11:$B$43,0),MATCH($H$8,SOMFP!$E$8:$P$8,0)),"") -> 2584
A41: Current Liabilities | E41: =SUM(E42:E48) -> 1886579.9 | G41: =SUM(G42:G48) -> 1822545.7 | H41: =SUM(H42:H48) -> 1869029.8
B42: =SOMFP!B40 -> Accounts Payable (A/P) | E42: =IFERROR(INDEX(SOMFP!$E$11:$P$48,MATCH($B42,SOMFP!$B$11:$B$43,0),MATCH($E$8,SOMFP!$E$8:$P$8,0)),"") -> 488234.51 | G42: =IFERROR(INDEX(SOMFP!$E$11:$P$48,MATCH($B42,SOMFP!$B$11:$B$43,0),MATCH($G$8,SOMFP!$E$8:$P$8,0)),"") -> 482625.15 | H42: =IFERROR(INDEX(SOMFP!$E$11:$P$48,MATCH($B42,SOMFP!$B$11:$B$43,0),MATCH($H$8,SOMFP!$E$8:$P$8,0)),"") -> 479530.81
B43: =SOMFP!B41 -> Machine Rent Payable | E43: =IFERROR(INDEX(SOMFP!$E$11:$P$48,MATCH($B43,SOMFP!$B$11:$B$43,0),MATCH($E$8,SOMFP!$E$8:$P$8,0)),"") -> 753208.48 | G43: =IFERROR(INDEX(SOMFP!$E$11:$P$48,MATCH($B43,SOMFP!$B$11:$B$43,0),MATCH($G$8,SOMFP!$E$8:$P$8,0)),"") -> 766712.98 | H43: =IFERROR(INDEX(SOMFP!$E$11:$P$48,MATCH($B43,SOMFP!$B$11:$B$43,0),MATCH($H$8,SOMFP!$E$8:$P$8,0)),"") -> 744212.98
B44: =SOMFP!B42 -> Loan from Infusion | E44: =IFERROR(INDEX(SOMFP!$E$11:$P$48,MATCH($B44,SOMFP!$B$11:$B$43,0),MATCH($E$8,SOMFP!$E$8:$P$8,0)),"") -> 100000 | G44: =IFERROR(INDEX(SOMFP!$E$11:$P$48,MATCH($B44,SOMFP!$B$11:$B$43,0),MATCH($G$8,SOMFP!$E$8:$P$8,0)),"") -> 100000 | H44: =IFERROR(INDEX(SOMFP!$E$11:$P$48,MATCH($B44,SOMFP!$B$11:$B$43,0),MATCH($H$8,SOMFP!$E$8:$P$8,0)),"") -> 100000
B45: =SOMFP!B43 -> Loan From Mr saeed | E45: =IFERROR(INDEX(SOMFP!$E$11:$P$59,MATCH($B45,SOMFP!$B$11:$B$59,0),MATCH($E$8,SOMFP!$E$8:$P$8,0)),"") -> 649786 | G45: =IFERROR(INDEX(SOMFP!$E$11:$P$59,MATCH($B45,SOMFP!$B$11:$B$59,0),MATCH($G$8,SOMFP!$E$8:$P$8,0)),"") -> 579786 | H45: =IFERROR(INDEX(SOMFP!$E$11:$P$48,MATCH($B45,SOMFP!$B$11:$B$43,0),MATCH($H$8,SOMFP!$E$8:$P$8,0)),"") -> 545286
B46: =SOMFP!B44 -> Salaries & wages payable | E46: =IFERROR(INDEX(SOMFP!$E$11:$P$59,MATCH($B46,SOMFP!$B$11:$B$59,0),MATCH($E$8,SOMFP!$E$8:$P$8,0)),"") -> 39200 | G46: =IFERROR(INDEX(SOMFP!$E$11:$P$59,MATCH($B46,SOMFP!$B$11:$B$59,0),MATCH($G$8,SOMFP!$E$8:$P$8,0)),"") -> 37416
B47: =SOMFP!B45 -> Transguard Payable | E47: =IFERROR(INDEX(SOMFP!$E$11:$P$59,MATCH($B47,SOMFP!$B$11:$B$59,0),MATCH($E$8,SOMFP!$E$8:$P$8,0)),"") -> -7500 | G47: =IFERROR(INDEX(SOMFP!$E$11:$P$59,MATCH($B47,SOMFP!$B$11:$B$59,0),MATCH($G$8,SOMFP!$E$8:$P$8,0)),"") -> -7500
...

Sheet SOMFP
A2: =Cover!A12 -> Western Vending Machines LLC
A3: =Cover!A13 -> DUABI UAE
A5: STATEMENT OF FINANCIAL POSITION
A6: =SOFP!A6 -> As On June - 2025
A7: Amount in AED
A8: Particulars | C8: Note | E8: =+SOMCI!F9 -> 45474 | F8: =DATE(YEAR(E8),MONTH(E8)+1,1) -> 45505 | G8: =DATE(YEAR(F8),MONTH(F8)+1,1) -> 45536 | H8: =DATE(YEAR(G8),MONTH(G8)+1,1) -> 45566 | I8: =DATE(YEAR(H8),MONTH(H8)+1,1) -> 45597 | J8: =DATE(YEAR(I8),MONTH(I8)+1,1) -> 45627 | K8: =DATE(YEAR(J8),MONTH(J8)+1,1) -> 45658 | L8: =DATE(YEAR(K8),MONTH(K8)+1,1) -> 45689 | M8: =DATE(YEAR(L8),MONTH(L8)+1,1) -> 45717 | ... P8: =DATE(YEAR(O8),MONTH(O8)+1,1) -> 45809
A9: Assets:
A10: Fixed Assets | E10: =SUM(E11:E13) -> 555177.55 | F10: =SUM(F11:F13) -> 552977.55 | G10: =SUM(G11:G13) -> 597282.55 | H10: =SUM(H11:H13) -> 595082.55 | I10: =SUM(I11:I13) -> 624990.55 | J10: =SUM(J11:J13) -> 623890.55 | K10: =SUM(K11:K13) -> 622790.55 | L10: =SUM(L11:L13) -> 621690.55 | ... P10: =SUM(P11:P13) -> 622270.55
B12: Property and equipement | E12: 555177.55 | F12: 552977.55 | G12: 597282.55 | H12: 595082.55 | I12: 624990.55 | J12: 623890.55 | K12: 622790.55 | L12: 621690.55 | M12: 627520.55 | N12: 626420.55 | O12: 622270.55 | P12: ='Linked BS'!B58 -> 622270.55
A14: Current Assets | E14: =SUM(E15:E24) -> 448313.34 | F14: =SUM(F15:F24) -> 440763.68 | G14: =SUM(G15:G24) -> 440993.04 | H14: =SUM(H15:H24) -> 399080.04 | I14: =SUM(I15:I24) -> 490269.59 | J14: =SUM(J15:J24) -> 409144.03 | K14: =SUM(K15:K24) -> 408516.63 | L14: =SUM(L15:L24) -> 459578.57 | ... P14: =SUM(P15:P24) -> 386321.55
B15: ADIB | E15: 29294.84 | F15: 55537.77 | G15: 31129.65 | H15: 2428.1 | I15: 91938.33 | J15: 16819.36 | K15: 17005.39 | L15: 53106.73 | M15: 6831.06 | N15: 17866.73 | O15: 20188.56 | P15: ='Linked BS'!B12 -> 2948.1
B16: Ajman Petty-Cash | E16: -299.05 | F16: 196.95 | G16: 196.95 | H16: -281.1 | I16: -193.1 | J16: -17.1 | K16: 158.9 | L16: 113.9 | M16: 25.9 | N16: -62.1 | O16: -62.1 | P16: ='Linked BS'!B13 -> -62.1
B17: Main Cash (Collection) | E17: 15873.34 | F17: -7016.66 | G17: 1087.34 | H17: 4118.34 | I17: -2948.66 | J17: 878.34 | K17: 5338.34 | L17: 3156.34 | M17: 5789.34 | N17: 5991.34 | O17: 5345.34 | P17: ='Linked BS'!B14 -> 6684.34
B18: Advance to employee | E18: 121786.5 | F18: 121286.5 | G18: 104206.5 | H18: 109706.5 | I18: 109706.5 | J18: 109206.5 | K18: 109206.5 | L18: 109206.5 | M18: 109206.5 | N18: 109206.5 | O18: 109206.5 | P18: ='Linked BS'!B15 -> 109206.5
B19: Cash in Machines | E19: 50331 | F19: 50331 | G19: 50331 | H19: 50331 | I19: 50331 | J19: 50331 | K19: 50331 | L19: 50331 | M19: 50331 | N19: 50331 | O19: 50331 | P19: ='Linked BS'!B16 -> 49326
B20: Fuel Adnoc balance | E20: 1746.83 | F20: 2603.29 | G20: 3770.49 | H20: 1504.06 | I20: 4885.28 | J20: 868 | K20: 733.47 | L20: 2543.82 | M20: 4719.39 | N20: 934.07 | O20: 1288.4 | P20: ='Linked BS'!B17 -> 1645.4
B21: Inventory | E21: 97915.13 | F21: 96602.75 | G21: 107992.61 | H21: 106629.98 | I21: 107880.66 | J21: 104441.17 | K21: 102126.13 | L21: 98912.93 | M21: 93513.04 | N21: 94216.65 | O21: 83871.71 | P21: ='Linked BS'!B18 -> 86361.36
B22: Prepayments | E22: 93014.78 | F22: 82572.11 | G22: 102788.53 | H22: 85053.19 | I22: 88189.61 | J22: 86036.79 | K22: 79205.03 | L22: 82256.55 | M22: 77348.64 | N22: 69053.73 | O22: 60836.31 | P22: ='Linked BS'!B35 -> 66258.67
B23: Accounts receivable | E23: 4199.97 | F23: 4199.97 | G23: 5039.97 | H23: 5039.97 | I23: 5879.97 | J23: 5879.97 | K23: 9111.87 | L23: 24450.8 | M23: 27196.03 | N23: 27243.28 | O23: 27243.28 | P23: ='Linked BS'!B9 -> 27243.28
B24: Securities | E24: 34450 | F24: 34450 | G24: 34450 | H24: 34550 | I24: 34600 | J24: 34700 | K24: 35300 | L24: 35500 | M24: 36060 | N24: 36060 | O24: 36710 | P24: ='Linked BS'!B42 -> 36710
A26: Total Assets | E26: =+E10+E14 -> 1003490.9 | F26: =+F10+F14 -> 993741.23 | G26: =+G10+G14 -> 1038275.6 | H26: =+H10+H14 -> 994162.59 | I26: =+I10+I14 -> 1115260.1 | J26: =+J10+J14 -> 1033034.6 | K26: =+K10+K14 -> 1031307.2 | L26: =+L10+L14 -> 1081269.1 | ... P26: =+P10+P14 -> 1008592.1
A27: Equity & Liabilities:
A28: Equity | E28: =SUM(E29:E33) -> -277520.66 | F28: =SUM(F29:F33) -> -311876.47 | G28: =SUM(G29:G33) -> -344697.49 | H28: =SUM(H29:H33) -> -431078.34 | I28: =SUM(I29:I33) -> -443822.07 | J28: =SUM(J29:J33) -> -469270.86 | K28: =SUM(K29:K33) -> -571710.96 | L28: =SUM(L29:L33) -> -602342.01 | ... P28: =SUM(P29:P33) -> -877987.75
B29: Net Income | E29: -221941.63 | F29: -256329.84 | G29: -289150.86 | H29: -375531.71 | I29: -388275.44 | J29: -413724.23 | K29: -102431.13 | L29: -133054.91 | M29: -210598.12 | N29: -261021.92 | O29: -336029.07 | P29: ='Linked BS'!B87 -> -408700.65
B30: Drawings | E30: 267396.82 | F30: 267396.82 | G30: 267396.82 | H30: 267396.82 | I30: 267396.82 | J30: 267396.82 | K30: 267396.82 | L30: 267396.82 | M30: 267396.82 | N30: 267396.82 | O30: 267396.82 | P30: ='Linked BS'!B88 -> 267396.82
B31: Opening Balance Equity | E31: 352691.19 | F31: 352723.59 | G31: 352723.59 | H31: 352723.59 | I31: 352723.59 | J31: 352723.59 | K31: 352723.59 | L31: 352723.59 | M31: 352723.59 | N31: 352723.59 | O31: 352723.59 | P31: ='Linked BS'!B89 -> 352723.59
B32: Retained Earnings | E32: -803620.56 | F32: -803620.56 | G32: -803620.56 | H32: -803620.56 | I32: -803620.56 | J32: -803620.56 | K32: -1217353.8 | L32: -1217361 | M32: -1217361 | N32: -1217361 | O32: -1217361 | P32: ='Linked BS'!B90 -> -1217361
B33: Share holder current account | E33: 127953.52 | F33: 127953.52 | G33: 127953.52 | H33: 127953.52 | I33: 127953.52 | J33: 127953.52 | K33: 127953.52 | L33: 127953.52 | M33: 127953.52 | N33: 127953.52 | O33: 127953.52 | P33: ='Linked BS'!B91 -> 127953.52
A35: Non-current Liabilities | E35: =SUM(E36:E37) -> 29210 | F35: =SUM(F36:F37) -> 22084 | G35: =SUM(G36:G37) -> 14958 | H35: =SUM(H36:H37) -> 706 | I35: =SUM(I36:I37) -> 24588 | J35: =SUM(J36:J37) -> 22004 | K35: =SUM(K36:K37) -> 10336 | L35: =SUM(L36:L37) -> 7752 | ... P35: =SUM(P36:P37) -> 0
B37: Leased Vehicle | E37: 29210 | F37: 22084 | G37: 14958 | H37: 706 | I37: 24588 | J37: 22004 | K37: 10336 | L37: 7752 | M37: 5168 | N37: 2584 | O37: 0 | P37: ='Linked BS'!B83 -> 0
A39: Current Liabilities | E39: =SUM(E40:E46) -> 1251801.6 | F39: =SUM(F40:F46) -> 1283533.7 | G39: =SUM(G40:G46) -> 1368015.1 | H39: =SUM(H40:H46) -> 1424534.9 | I39: =SUM(I40:I46) -> 1534494.2 | J39: =SUM(J40:J46) -> 1480301.4 | K39: =SUM(K40:K46) -> 1592682.1 | L39: =SUM(L40:L46) -> 1675859.1 | ... P39: =SUM(P40:P46) -> 1886579.9
B40: Accounts Payable (A/P) | E40: 415337.73 | F40: 443741.62 | G40: 464079.69 | H40: 464786.16 | I40: 448207.73 | J40: 424476.68 | K40: 429271.98 | L40: 446938.99 | M40: 459993.56 | N40: 479530.81 | O40: 482625.15 | P40: ='Linked BS'!B63 -> 488234.51
B41: Machine Rent Payable | E41: 672869.98 | F41: 695369.98 | G41: 717869.98 | H41: 704043.73 | I41: 726543.73 | J41: 690217.48 | K41: 712717.48 | L41: 735217.48 | M41: 757717.48 | N41: 744212.98 | O41: 766712.98 | P41: ='Linked BS'!B65+'Linked BS'!B70+'Linked BS'!B71 -> 753208.48
B42: Loan from Infusion | E42: 100000 | F42: 100000 | G42: 100000 | H42: 100000 | I42: 100000 | J42: 100000 | K42: 100000 | L42: 100000 | M42: 100000 | N42: 100000 | O42: 100000 | P42: ='Linked BS'!B68 -> 100000
B43: Loan From Mr saeed | E43: 128723 | F43: 128723 | G43: 168723 | H43: 248723 | I43: 348723 | J43: 348723 | K43: 445723 | L43: 478286 | M43: 495286 | N43: 545286 | O43: 579786 | P43: ='Linked BS'!B69 -> 649786
B44: Salaries & wages payable | E44: 31900 | F44: 32734 | G44: 34084 | H44: 37200 | I44: 34550 | J44: 34500 | K44: 32500 | L44: 35250 | M44: 32866 | N44: 34950 | O44: 37416 | P44: ='Linked BS'!B74 -> 39200
B45: Transguard Payable | E45: 2500 | F45: 5000 | G45: 10000 | H45: 5000 | I45: 7500 | J45: 10000 | K45: 10000 | L45: 15000 | M45: 0 | N45: 0 | O45: -7500 | P45: ='Linked BS'!B76 -> -7500
B46: Other Payables | E46: -99529.16 | F46: -122034.9 | G46: -126741.59 | H46: -135217.96 | I46: -131030.25 | J46: -127615.72 | K46: -137530.32 | L46: -134833.34 | M46: -132604.37 | N46: -138993.02 | O46: -136494.41 | P46: ='Linked BS'!B66+'Linked BS'!B73+'Linked BS'!B75+'Linked BS'!B78+'Linked BS'!B79 -> -136349.14
A48: Total Equity & Liabilities | E48: =+E28+E35+E39 -> 1003490.9 | F48: =+F28+F35+F39 -> 993741.23 | G48: =+G28+G35+G39 -> 1038275.6 | H48: =+H28+H35+H39 -> 994162.59 | I48: =+I28+I35+I39 -> 1115260.1 | J48: =+J28+J35+J39 -> 1033034.6 | K48: =+K28+K35+K39 -> 1031307.2 | L48: =+L28+L35+L39 -> 1081269.1 | ... P48: =+P28+P35+P39 -> 1008592.1
A50: Error | E50: =+E26-E48 -> 0 | F50: =+F26-F48 -> 0 | G50: =+G26-G48 -> 0 | H50: =+H26-H48 -> 0 | I50: =+I26-I48 -> 0 | J50: =+J26-J48 -> 0 | K50: =+K26-K48 -> 0 | L50: =+L26-L48 -> 0 | ... P50: =+P26-P48 -> 0

Sheet SOCI
A2: =Cover!A12 -> Western Vending Machines LLC
A3: =Cover!A13 -> DUABI UAE
A5: STATEMENT OF COMPREHENSIVE INCOME
A6: =Galance!D20 -> For the month of June - 2025
A7: Amount in AED
A8: Particulars | D8: Notes | F8: =VLOOKUP(Cover!$C$3,Cover!$G$4:$Q$17,4,) -> 45809 | H8: =DATE(YEAR(F8),MONTH(F8)-1,1) -> 45778 | J8: YTD
A10: Revenue | F10: =SUM(F11:F16) -> 67980.55 | H10: =SUM(H11:H16) -> 87520.02 | J10: =SUM(J11:J16) -> 1384387.2
B11: =SOMCI!B12 -> Sales | F11: =IFERROR(INDEX(SOMCI!$F$12:$Q$66,MATCH(SOCI!$B11,SOMCI!$B$12:$B$66,0),MATCH(SOCI!F$8,SOMCI!$F$9:$Q$9,0)),"") -> 41684.76 | H11: =IFERROR(INDEX(SOMCI!$F$12:$R$66,MATCH(SOCI!$B11,SOMCI!$B$12:$B$66,0),MATCH(SOCI!H$8,SOMCI!$F$9:$R$9,0)),"") -> 54051.43 | J11: =IFERROR(INDEX(SOMCI!$F$12:$R$66,MATCH(SOCI!$B11,SOMCI!$B$12:$B$66,0),MATCH(SOCI!J$8,SOMCI!$F$9:$R$9,0)),"") -> 945931.38
B12: =SOMCI!B13 -> Sales of Product Income | F12: =IFERROR(INDEX(SOMCI!$F$12:$Q$66,MATCH(SOCI!$B12,SOMCI!$B$12:$B$66,0),MATCH(SOCI!F$8,SOMCI!$F$9:$Q$9,0)),"") -> 0 | H12: =IFERROR(INDEX(SOMCI!$F$12:$R$66,MATCH(SOCI!$B12,SOMCI!$B$12:$B$66,0),MATCH(SOCI!H$8,SOMCI!$F$9:$R$9,0)),"") -> 0 | J12: =IFERROR(INDEX(SOMCI!$F$12:$R$66,MATCH(SOCI!$B12,SOMCI!$B$12:$B$66,0),MATCH(SOCI!J$8,SOMCI!$F$9:$R$9,0)),"") -> 6432
B13: =SOMCI!B14 -> Credit card Sales | F13: =IFERROR(INDEX(SOMCI!$F$12:$Q$66,MATCH(SOCI!$B13,SOMCI!$B$12:$B$66,0),MATCH(SOCI!F$8,SOMCI!$F$9:$Q$9,0)),"") -> 26295.79 | H13: =IFERROR(INDEX(SOMCI!$F$12:$R$66,MATCH(SOCI!$B13,SOMCI!$B$12:$B$66,0),MATCH(SOCI!H$8,SOMCI!$F$9:$R$9,0)),"") -> 33468.59 | J13: =IFERROR(INDEX(SOMCI!$F$12:$R$66,MATCH(SOCI!$B13,SOMCI!$B$12:$B$66,0),MATCH(SOCI!J$8,SOMCI!$F$9:$R$9,0)),"") -> 430423.79
B14: =SOMCI!B15 -> CID alain contract | F14: =IFERROR(INDEX(SOMCI!$F$12:$Q$66,MATCH(SOCI!$B14,SOMCI!$B$12:$B$66,0),MATCH(SOCI!F$8,SOMCI!$F$9:$Q$9,0)),"") -> 0 | H14: =IFERROR(INDEX(SOMCI!$F$12:$Q$66,MATCH(SOCI!$B14,SOMCI!$B$12:$B$66,0),MATCH(SOCI!H$8,SOMCI!$F$9:$Q$9,0)),"") -> 0 | J14: =IFERROR(INDEX(SOMCI!$F$12:$R$66,MATCH(SOCI!$B14,SOMCI!$B$12:$B$66,0),MATCH(SOCI!J$8,SOMCI!$F$9:$R$9,0)),"") -> 0
B15: =SOMCI!B16 -> Homie portal AL WAHA | F15: =IFERROR(INDEX(SOMCI!$F$12:$Q$66,MATCH(SOCI!$B15,SOMCI!$B$12:$B$66,0),MATCH(SOCI!F$8,SOMCI!$F$9:$Q$9,0)),"") -> 0 | H15: =IFERROR(INDEX(SOMCI!$F$12:$Q$66,MATCH(SOCI!$B15,SOMCI!$B$12:$B$66,0),MATCH(SOCI!H$8,SOMCI!$F$9:$Q$9,0)),"") -> 0 | J15: =IFERROR(INDEX(SOMCI!$F$12:$R$66,MATCH(SOCI!$B15,SOMCI!$B$12:$B$66,0),MATCH(SOCI!J$8,SOMCI!$F$9:$R$9,0)),"") -> 1600
B16: =SOMCI!B17 -> MOI Deewan Sales | F16: =IFERROR(INDEX(SOMCI!$F$12:$Q$66,MATCH(SOCI!$B16,SOMCI!$B$12:$B$66,0),MATCH(SOCI!F$8,SOMCI!$F$9:$Q$9,0)),"") -> 0 | H16: =IFERROR(INDEX(SOMCI!$F$12:$Q$66,MATCH(SOCI!$B16,SOMCI!$B$12:$B$66,0),MATCH(SOCI!H$8,SOMCI!$F$9:$Q$9,0)),"") -> 0 | J16: =IFERROR(INDEX(SOMCI!$F$12:$R$66,MATCH(SOCI!$B16,SOMCI!$B$12:$B$66,0),MATCH(SOCI!J$8,SOMCI!$F$9:$R$9,0)),"") -> 0
A17: Direct Expenses | F17: =SUM(F18:F19) -> 38352.35 | G17: =SUM(G18:G19) -> 0 | H17: =SUM(H18:H19) -> 42536.15 | I17: =SUM(I18:I19) -> 0 | J17: =SUM(J18:J19) -> 679707.6
F18: =IFERROR(INDEX(SOMCI!$F$12:$Q$66,MATCH(SOCI!$B18,SOMCI!$B$12:$B$66,0),MATCH(SOCI!F$8,SOMCI!$F$9:$Q$9,0)),"") | H18: =IFERROR(INDEX(SOMCI!$F$12:$Q$66,MATCH(SOCI!$B18,SOMCI!$B$12:$B$66,0),MATCH(SOCI!H$8,SOMCI!$F$9:$Q$9,0)),"") | J18: =IFERROR(INDEX(SOMCI!$F$12:$R$66,MATCH(SOCI!$B18,SOMCI!$B$12:$B$66,0),MATCH(SOCI!J$8,SOMCI!$F$9:$R$9,0)),"")
B19: =SOMCI!B20 -> COST OF SALES | F19: =IFERROR(INDEX(SOMCI!$F$12:$Q$66,MATCH(SOCI!$B19,SOMCI!$B$12:$B$66,0),MATCH(SOCI!F$8,SOMCI!$F$9:$Q$9,0)),"") -> 38352.35 | H19: =IFERROR(INDEX(SOMCI!$F$12:$Q$66,MATCH(SOCI!$B19,SOMCI!$B$12:$B$66,0),MATCH(SOCI!H$8,SOMCI!$F$9:$Q$9,0)),"") -> 42536.15 | J19: =IFERROR(INDEX(SOMCI!$F$12:$R$66,MATCH(SOCI!$B19,SOMCI!$B$12:$B$66,0),MATCH(SOCI!J$8,SOMCI!$F$9:$R$9,0)),"") -> 679707.6
A20: Gross Profit / (Loss) | F20: =+F10-F17 -> 29628.2 | G20: =+G10-G17 -> 0 | H20: =+H10-H17 -> 44983.87 | J20: =+J10-J17 -> 704679.57
A21: Indirect Expenses | F21: =IFERROR(INDEX(SOMCI!$F$12:$Q$66,MATCH(SOCI!#REF!,SOMCI!$B$12:$B$66,0),MATCH(SOCI!F$8,SOMCI!$F$9:$Q$9,0)),"") | H21: =IFERROR(INDEX(SOMCI!$F$12:$Q$66,MATCH(SOCI!#REF!,SOMCI!$B$12:$B$66,0),MATCH(SOCI!H$8,SOMCI!$F$9:$Q$9,0)),"")
A22: Operating Expenses | F22: =SUM(F23:F29) -> 58793 | H22: =SUM(H23:H29) -> 58357.67 | J22: =SUM(J23:J29) -> 702399.43
B23: Salaries and Wages of Staff in Operation | F23: =IFERROR(INDEX(SOMCI!$F$12:$Q$66,MATCH(SOCI!$B23,SOMCI!$B$12:$B$66,0),MATCH(SOCI!F$8,SOMCI!$F$9:$Q$9,0)),"") -> 21100 | H23: =IFERROR(INDEX(SOMCI!$F$12:$Q$66,MATCH(SOCI!$B23,SOMCI!$B$12:$B$66,0),MATCH(SOCI!H$8,SOMCI!$F$9:$Q$9,0)),"") -> 21100 | J23: =IFERROR(INDEX(SOMCI!$F$12:$R$66,MATCH(SOCI!$B23,SOMCI!$B$12:$B$66,0),MATCH(SOCI!J$8,SOMCI!$F$9:$R$9,0)),"") -> 253200
B24: Machine Rent Expense | F24: =IFERROR(INDEX(SOMCI!$F$12:$Q$66,MATCH(SOCI!$B24,SOMCI!$B$12:$B$66,0),MATCH(SOCI!F$8,SOMCI!$F$9:$Q$9,0)),"") -> 22500 | H24: =IFERROR(INDEX(SOMCI!$F$12:$Q$66,MATCH(SOCI!$B24,SOMCI!$B$12:$B$66,0),MATCH(SOCI!H$8,SOMCI!$F$9:$Q$9,0)),"") -> 22500 | J24: =IFERROR(INDEX(SOMCI!$F$12:$R$66,MATCH(SOCI!$B24,SOMCI!$B$12:$B$66,0),MATCH(SOCI!J$8,SOMCI!$F$9:$R$9,0)),"") -> 270000
B25: Machine Repair & Maintenance | F25: =IFERROR(INDEX(SOMCI!$F$12:$Q$66,MATCH(SOCI!$B25,SOMCI!$B$12:$B$66,0),MATCH(SOCI!F$8,SOMCI!$F$9:$Q$9,0)),"") -> 0 | H25: =IFERROR(INDEX(SOMCI!$F$12:$Q$66,MATCH(SOCI!$B25,SOMCI!$B$12:$B$66,0),MATCH(SOCI!H$8,SOMCI!$F$9:$Q$9,0)),"") -> 845 | J25: =IFERROR(INDEX(SOMCI!$F$12:$R$66,MATCH(SOCI!$B25,SOMCI!$B$12:$B$66,0),MATCH(SOCI!J$8,SOMCI!$F$9:$R$9,0)),"") -> 7844
B26: Vehicle Repairs and Maintenance | F26: =IFERROR(INDEX(SOMCI!$F$12:$Q$66,MATCH(SOCI!$B26,SOMCI!$B$12:$B$66,0),MATCH(SOCI!F$8,SOMCI!$F$9:$Q$9,0)),"") -> 6950 | H26: =IFERROR(INDEX(SOMCI!$F$12:$Q$66,MATCH(SOCI!$B26,SOMCI!$B$12:$B$66,0),MATCH(SOCI!H$8,SOMCI!$F$9:$Q$9,0)),"") -> 4267 | J26: =IFERROR(INDEX(SOMCI!$F$12:$R$66,MATCH(SOCI!$B26,SOMCI!$B$12:$B$66,0),MATCH(SOCI!J$8,SOMCI!$F$9:$R$9,0)),"") -> 40566
B27: Rent Expense | F27: =IFERROR(INDEX(SOMCI!$F$12:$Q$66,MATCH(SOCI!$B27,SOMCI!$B$12:$B$66,0),MATCH(SOCI!F$8,SOMCI!$F$9:$Q$9,0)),"") -> 0 | H27: =IFERROR(INDEX(SOMCI!$F$12:$Q$66,MATCH(SOCI!$B27,SOMCI!$B$12:$B$66,0),MATCH(SOCI!H$8,SOMCI!$F$9:$Q$9,0)),"") -> 0 | J27: =IFERROR(INDEX(SOMCI!$F$12:$R$66,MATCH(SOCI!$B27,SOMCI!$B$12:$B$66,0),MATCH(SOCI!J$8,SOMCI!$F$9:$R$9,0)),"") -> 0
B28: Fuel Expense | F28: =IFERROR(INDEX(SOMCI!$F$12:$Q$66,MATCH(SOCI!$B28,SOMCI!$B$12:$B$66,0),MATCH(SOCI!F$8,SOMCI!$F$9:$Q$9,0)),"") -> 7143 | H28: =IFERROR(INDEX(SOMCI!$F$12:$Q$66,MATCH(SOCI!$B28,SOMCI!$B$12:$B$66,0),MATCH(SOCI!H$8,SOMCI!$F$9:$Q$9,0)),"") -> 9645.67 | J28: =IFERROR(INDEX(SOMCI!$F$12:$R$66,MATCH(SOCI!$B28,SOMCI!$B$12:$B$66,0),MATCH(SOCI!J$8,SOMCI!$F$9:$R$9,0)),"") -> 128789.43
B29: Freight And Delivery | F29: =IFERROR(INDEX(SOMCI!$F$12:$Q$66,MATCH(SOCI!$B29,SOMCI!$B$12:$B$66,0),MATCH(SOCI!F$8,SOMCI!$F$9:$Q$9,0)),"") -> 1100 | H29: =IFERROR(INDEX(SOMCI!$F$12:$Q$66,MATCH(SOCI!$B29,SOMCI!$B$12:$B$66,0),MATCH(SOCI!H$8,SOMCI!$F$9:$Q$9,0)),"") -> 0 | J29: =IFERROR(INDEX(SOMCI!$F$12:$R$66,MATCH(SOCI!$B29,SOMCI!$B$12:$B$66,0),MATCH(SOCI!J$8,SOMCI!$F$9:$R$9,0)),"") -> 2000
A30: Administrative Exp. | F30: =SUM(F31:F53) -> 43973.02 | H30: =SUM(H31:H53) -> 59307.36 | J30: =SUM(J31:J53) -> 582074.17
B31: Salaries and Wages | F31: =IFERROR(INDEX(SOMCI!$F$12:$Q$66,MATCH(SOCI!$B31,SOMCI!$B$12:$B$66,0),MATCH(SOCI!F$8,SOMCI!$F$9:$Q$9,0)),"") -> 14100 | H31: =IFERROR(INDEX(SOMCI!$F$12:$Q$66,MATCH(SOCI!$B31,SOMCI!$B$12:$B$66,0),MATCH(SOCI!H$8,SOMCI!$F$9:$Q$9,0)),"") -> 15016 | J31: =IFERROR(INDEX(SOMCI!$F$12:$R$66,MATCH(SOCI!$B31,SOMCI!$B$12:$B$66,0),MATCH(SOCI!J$8,SOMCI!$F$9:$R$9,0)),"") -> 158582
B32: Travel & Transport | F32: =IFERROR(INDEX(SOMCI!$F$12:$Q$66,MATCH(SOCI!$B32,SOMCI!$B$12:$B$66,0),MATCH(SOCI!F$8,SOMCI!$F$9:$Q$9,0)),"") -> 0 | H32: =IFERROR(INDEX(SOMCI!$F$12:$Q$66,MATCH(SOCI!$B32,SOMCI!$B$12:$B$66,0),MATCH(SOCI!H$8,SOMCI!$F$9:$Q$9,0)),"") -> 584 | J32: =IFERROR(INDEX(SOMCI!$F$12:$R$66,MATCH(SOCI!$B32,SOMCI!$B$12:$B$66,0),MATCH(SOCI!J$8,SOMCI!$F$9:$R$9,0)),"") -> 1620
B33: Office Repairs and Maintenance | F33: =IFERROR(INDEX(SOMCI!$F$12:$Q$66,MATCH(SOCI!$B33,SOMCI!$B$12:$B$66,0),MATCH(SOCI!F$8,SOMCI!$F$9:$Q$9,0)),"") -> 1200 | H33: =IFERROR(INDEX(SOMCI!$F$12:$Q$66,MATCH(SOCI!$B33,SOMCI!$B$12:$B$66,0),MATCH(SOCI!H$8,SOMCI!$F$9:$Q$9,0)),"") -> 0 | J33: =IFERROR(INDEX(SOMCI!$F$12:$R$66,MATCH(SOCI!$B33,SOMCI!$B$12:$B$66,0),MATCH(SOCI!J$8,SOMCI!$F$9:$R$9,0)),"") -> 1227
B34: Meal And Entertainmnet | F34: =IFERROR(INDEX(SOMCI!$F$12:$Q$66,MATCH(SOCI!$B34,SOMCI!$B$12:$B$66,0),MATCH(SOCI!F$8,SOMCI!$F$9:$Q$9,0)),"") -> 0 | H34: =IFERROR(INDEX(SOMCI!$F$12:$Q$66,MATCH(SOCI!$B34,SOMCI!$B$12:$B$66,0),MATCH(SOCI!H$8,SOMCI!$F$9:$Q$9,0)),"") -> 0 | J34: =IFERROR(INDEX(SOMCI!$F$12:$R$66,MATCH(SOCI!$B34,SOMCI!$B$12:$B$66,0),MATCH(SOCI!J$8,SOMCI!$F$9:$R$9,0)),"") -> 0
B35: Printing and Stationary | F35: =IFERROR(INDEX(SOMCI!$F$12:$Q$66,MATCH(SOCI!$B35,SOMCI!$B$12:$B$66,0),MATCH(SOCI!F$8,SOMCI!$F$9:$Q$9,0)),"") -> 0 | H35: =IFERROR(INDEX(SOMCI!$F$12:$Q$66,MATCH(SOCI!$B35,SOMCI!$B$12:$B$66,0),MATCH(SOCI!H$8,SOMCI!$F$9:$Q$9,0)),"") -> 90 | J35: =IFERROR(INDEX(SOMCI!$F$12:$R$66,MATCH(SOCI!$B35,SOMCI!$B$12:$B$66,0),MATCH(SOCI!J$8,SOMCI!$F$9:$R$9,0)),"") -> 2580
B36: Utiliies Expense | F36: =IFERROR(INDEX(SOMCI!$F$12:$Q$66,MATCH(SOCI!$B36,SOMCI!$B$12:$B$66,0),MATCH(SOCI!F$8,SOMCI!$F$9:$Q$9,0)),"") -> 0 | H36: =IFERROR(INDEX(SOMCI!$F$12:$Q$66,MATCH(SOCI!$B36,SOMCI!$B$12:$B$66,0),MATCH(SOCI!H$8,SOMCI!$F$9:$Q$9,0)),"") -> 1377.88 | J36: =IFERROR(INDEX(SOMCI!$F$12:$R$66,MATCH(SOCI!$B36,SOMCI!$B$12:$B$66,0),MATCH(SOCI!J$8,SOMCI!$F$9:$R$9,0)),"") -> 11307.5
B37: Mobile & Communication | F37: =IFERROR(INDEX(SOMCI!$F$12:$Q$66,MATCH(SOCI!$B37,SOMCI!$B$12:$B$66,0),MATCH(SOCI!F$8,SOMCI!$F$9:$Q$9,0)),"") -> 0 | H37: =IFERROR(INDEX(SOMCI!$F$12:$Q$66,MATCH(SOCI!$B37,SOMCI!$B$12:$B$66,0),MATCH(SOCI!H$8,SOMCI!$F$9:$Q$9,0)),"") -> 4586.57 | J37: =IFERROR(INDEX(SOMCI!$F$12:$R$66,MATCH(SOCI!$B37,SOMCI!$B$12:$B$66,0),MATCH(SOCI!J$8,SOMCI!$F$9:$R$9,0)),"") -> 28812.23
B38: Office Supplies | F38: =IFERROR(INDEX(SOMCI!$F$12:$Q$66,MATCH(SOCI!$B38,SOMCI!$B$12:$B$66,0),MATCH(SOCI!F$8,SOMCI!$F$9:$Q$9,0)),"") -> 0 | H38: =IFERROR(INDEX(SOMCI!$F$12:$Q$66,MATCH(SOCI!$B38,SOMCI!$B$12:$B$66,0),MATCH(SOCI!H$8,SOMCI!$F$9:$Q$9,0)),"") -> 610 | J38: =IFERROR(INDEX(SOMCI!$F$12:$R$66,MATCH(SOCI!$B38,SOMCI!$B$12:$B$66,0),MATCH(SOCI!J$8,SOMCI!$F$9:$R$9,0)),"") -> 3382
B39: Personal Expense Mr Saeed | F39: =IFERROR(INDEX(SOMCI!$F$12:$Q$66,MATCH(SOCI!$B39,SOMCI!$B$12:$B$66,0),MATCH(SOCI!F$8,SOMCI!$F$9:$Q$9,0)),"") -> 200 | H39: =IFERROR(INDEX(SOMCI!$F$12:$Q$66,MATCH(SOCI!$B39,SOMCI!$B$12:$B$66,0),MATCH(SOCI!H$8,SOMCI!$F$9:$Q$9,0)),"") -> 1700 | J39: =IFERROR(INDEX(SOMCI!$F$12:$R$66,MATCH(SOCI!$B39,SOMCI!$B$12:$B$66,0),MATCH(SOCI!J$8,SOMCI!$F$9:$R$9,0)),"") -> 1900
B40: Rent Apartment & Store Exp. Abu Dhabi | F40: =IFERROR(INDEX(SOMCI!$F$12:$Q$66,MATCH(SOCI!$B40,SOMCI!$B$12:$B$66,0),MATCH(SOCI!F$8,SOMCI!$F$9:$Q$9,0)),"") -> 3795 | H40: =IFERROR(INDEX(SOMCI!$F$12:$Q$66,MATCH(SOCI!$B40,SOMCI!$B$12:$B$66,0),MATCH(SOCI!H$8,SOMCI!$F$9:$Q$9,0)),"") -> 3686.62 | J40: =IFERROR(INDEX(SOMCI!$F$12:$R$66,MATCH(SOCI!$B40,SOMCI!$B$12:$B$66,0),MATCH(SOCI!J$8,SOMCI!$F$9:$R$9,0)),"") -> 44347.82
B41: Rent Apartment & Store Exp. Ajman | F41: =IFERROR(INDEX(SOMCI!$F$12:$Q$66,MATCH(SOCI!$B41,SOMCI!$B$12:$B$66,0),MATCH(SOCI!F$8,SOMCI!$F$9:$Q$9,0)),"") -> 3989.15 | H41: =IFERROR(INDEX(SOMCI!$F$12:$Q$66,MATCH(SOCI!$B41,SOMCI!$B$12:$B$66,0),MATCH(SOCI!H$8,SOMCI!$F$9:$Q$9,0)),"") -> 3989.15 | J41: =IFERROR(INDEX(SOMCI!$F$12:$R$66,MATCH(SOCI!$B41,SOMCI!$B$12:$B$66,0),MATCH(SOCI!J$8,SOMCI!$F$9:$R$9,0)),"") -> 42230.35
B42: Staff VISA Expense | F42: =IFERROR(INDEX(SOMCI!$F$12:$Q$66,MATCH(SOCI!$B42,SOMCI!$B$12:$B$66,0),MATCH(SOCI!F$8,SOMCI!$F$9:$Q$9,0)),"") -> 3267.14 | H42: =IFERROR(INDEX(SOMCI!$F$12:$Q$66,MATCH(SOCI!$B42,SOMCI!$B$12:$B$66,0),MATCH(SOCI!H$8,SOMCI!$F$9:$Q$9,0)),"") -> 2567.14 | J42: =IFERROR(INDEX(SOMCI!$F$12:$R$66,MATCH(SOCI!$B42,SOMCI!$B$12:$B$66,0),MATCH(SOCI!J$8,SOMCI!$F$9:$R$9,0)),"") -> 31505.68
... B53: Vehicle Registration Expense | F53: =IFERROR(INDEX(SOMCI!$F$12:$Q$66,MATCH(SOCI!$B53,SOMCI!$B$12:$B$66,0),MATCH(SOCI!F$8,SOMCI!$F$9:$Q$9,0)),"") -> 0 | H53: =IFERROR(INDEX(SOMCI!$F$12:$Q$66,MATCH(SOCI!$B53,SOMCI!$B$12:$B$66,0),MATCH(SOCI!H$8,SOMCI!$F$9:$Q$9,0)),"") -> 0 | J53: =IFERROR(INDEX(SOMCI!$F$12:$R$66,MATCH(SOCI!$B53,SOMCI!$B$12:$B$66,0),MATCH(SOCI!J$8,SOMCI!$F$9:$R$9,0)),"") -> 9550
...

Sheet SOMCI
A2: =Cover!A12 -> Western Vending Machines LLC
A3: =Cover!A13 -> DUABI UAE
A5: STATEMENT OF MONTHLY COMPREHENSIVE INCOME
A6: =SOCI!A6 -> For the month of June - 2025
A8: Amount in AED
A9: Particulars | D9: Notes | F9: 45474 | G9: =DATE(YEAR(F9),MONTH(F9)+1,1) -> 45505 | H9: =DATE(YEAR(G9),MONTH(G9)+1,1) -> 45536 | I9: =DATE(YEAR(H9),MONTH(H9)+1,1) -> 45566 | J9: =DATE(YEAR(I9),MONTH(I9)+1,1) -> 45597 | K9: =DATE(YEAR(J9),MONTH(J9)+1,1) -> 45627 | L9: =DATE(YEAR(K9),MONTH(K9)+1,1) -> 45658 | M9: =DATE(YEAR(L9),MONTH(L9)+1,1) -> 45689 | N9: =DATE(YEAR(M9),MONTH(M9)+1,1) -> 45717 | ... Q9: =DATE(YEAR(P9),MONTH(P9)+1,1) -> 45809 | R9: YTD
A11: Revenue | F11: =SUM(F12:F17) -> 136750.7 | G11: =SUM(G12:G17) -> 133153.09 | H11: =SUM(H12:H17) -> 147771.74 | I11: =SUM(I12:I17) -> 142417.37 | J11: =SUM(J12:J17) -> 178389.79 | K11: =SUM(K12:K17) -> 119041.63 | L11: =SUM(L12:L17) -> 109659.7 | M11: =SUM(M12:M17) -> 111884.84 | ... Q11: =SUM(Q12:Q17) -> 67980.55 | R11: =SUM(F11:Q11) -> 1384387.2
B12: Sales | F12: 108452.4 | G12: 97999.07 | H12: 106394.29 | I12: 95559.05 | J12: 133550.48 | K12: 78611.44 | L12: 68173.24 | M12: 72350.46 | N12: 35098.09 | O12: 54006.67 | P12: 54051.43 | Q12: =SUMIF('Linked IS'!$B$3:$B$69,SOMCI!B12,'Linked IS'!$D$3:$D$69) -> 41684.76 | R12: =SUM(F12:Q12) -> 945931.38
B13: Sales of Product Income | L13: 3078 | M13: 694.5 | N13: 2614.5 | O13: 45 | P13: 0 | Q13: =SUMIF('Linked IS'!$B$3:$B$69,SOMCI!B13,'Linked IS'!$D$3:$D$69) -> 0 | R13: =SUM(F13:Q13) -> 6432
B14: Credit card Sales | F14: 28298.3 | G14: 34354.02 | H14: 41377.45 | I14: 46858.32 | J14: 44039.31 | K14: 40430.19 | L14: 38408.46 | M14: 38839.88 | N14: 24228.86 | O14: 33824.62 | P14: 33468.59 | Q14: =SUMIF('Linked IS'!$B$3:$B$69,SOMCI!B14,'Linked IS'!$D$3:$D$69) -> 26295.79 | R14: =SUM(F14:Q14) -> 430423.79
B15: CID alain contract | F15: 0 | G15: 0 | H15: 0 | I15: 0 | J15: 0 | K15: 0 | L15: 0 | M15: 0 | N15: 0 | O15: 0 | P15: 0 | Q15: =SUMIF('Linked IS'!$B$3:$B$69,SOMCI!B15,'Linked IS'!$D$3:$D$69) -> 0 | R15: =SUM(F15:Q15) -> 0
B16: Homie portal AL WAHA | F16: 0 | G16: 800 | H16: 0 | I16: 0 | J16: 800 | K16: 0 | L16: 0 | M16: 0 | N16: 0 | O16: 0 | P16: 0 | Q16: =SUMIF('Linked IS'!$B$3:$B$69,SOMCI!B16,'Linked IS'!$D$3:$D$69) -> 0 | R16: =SUM(F16:Q16) -> 1600
B17: MOI Deewan Sales | F17: 0 | G17: 0 | H17: 0 | I17: 0 | J17: 0 | K17: 0 | L17: 0 | M17: 0 | N17: 0 | O17: 0 | P17: 0 | Q17: =SUMIF('Linked IS'!$B$3:$B$69,SOMCI!B17,'Linked IS'!$D$3:$D$69) -> 0 | R17: =SUM(F17:Q17) -> 0
A18: Direct Expenses | F18: =SUM(F19:F20) -> 67880.66 | G18: =SUM(G19:G20) -> 62184.86 | H18: =SUM(H19:H20) -> 66355.92 | I18: =SUM(I19:I20) -> 76644.68 | J18: =SUM(J19:J20) -> 79293.56 | K18: =SUM(K19:K20) -> 52331.51 | L18: =SUM(L19:L20) -> 60816.33 | M18: =SUM(M19:M20) -> 57339.56 | ... Q18: =SUM(Q19:Q20) -> 38352.35 | R18: =SUM(F18:Q18) -> 679707.6
R19: =SUM(F19:Q19) -> 0
B20: COST OF SALES | F20: 67880.66 | G20: 62184.86 | H20: 66355.92 | I20: 76644.68 | J20: 79293.56 | K20: 52331.51 | L20: 60816.33 | M20: 57339.56 | N20: 22914.83 | O20: 53057.19 | P20: 42536.15 | Q20: =SUMIF('Linked IS'!$B$3:$B$69,SOMCI!B20,'Linked IS'!$D$3:$D$69) -> 38352.35 | R20: =SUM(F20:Q20) -> 679707.6
A21: Gross Profit / (Loss) | F21: =+F11-F18 -> 68870.04 | G21: =+G11-G18 -> 70968.23 | H21: =+H11-H18 -> 81415.82 | I21: =+I11-I18 -> 65772.69 | J21: =+J11-J18 -> 99096.23 | K21: =+K11-K18 -> 66710.12 | L21: =+L11-L18 -> 48843.37 | M21: =+M11-M18 -> 54545.28 | ... R21: =+R11-R18 -> 704679.57
A22: Indirect Expenses | F22: =+F23+F31+F55 -> 100987.46 | G22: =+G23+G31+G55 -> 102689.25 | H22: =+H23+H31+H55 -> 133727.42 | I22: =+I23+I31+I55 -> 100157.03 | J22: =+J23+J31+J55 -> 111539.7 | K22: =+K23+K31+K55 -> 91200.3 | L22: =+L23+L31+L55 -> 147096.5 | M22: =+M23+M31+M55 -> 88613.98 | ... Q22: =+Q23+Q31+Q55 -> 103004.37 | R22: =SUM(F22:Q22) -> 1298557.3
A23: Operating Expenses | F23: =SUM(F24:F30) -> 62846.54 | G23: =SUM(G24:G30) -> 64808.8 | H23: =SUM(H24:H30) -> 59378.23 | I23: =SUM(I24:I30) -> 61480.2 | J23: =SUM(J24:J30) -> 57938.78 | K23: =SUM(K24:K30) -> 55040.28 | L23: =SUM(L24:L30) -> 62965.53 | M23: =SUM(M24:M30) -> 53068.65 | ... Q23: =SUM(Q24:Q30) -> 58793 | R23: =SUM(F23:Q23) -> 702399.43
B24: Salaries and Wages of Staff in Operation | F24: 21100 | G24: 21100 | H24: 21100 | I24: 21100 | J24: 21100 | K24: 21100 | L24: 21100 | M24: 21100 | N24: 21100 | O24: 21100 | P24: 21100 | Q24: =SUMIF('Linked IS'!$B$3:$B$69,SOMCI!B24,'Linked IS'!$D$3:$D$69) -> 21100 | R24: =SUM(F24:Q24) -> 253200
B25: Machine Rent Expense | F25: 22500 | G25: 22500 | H25: 22500 | I25: 22500 | J25: 22500 | K25: 22500 | L25: 22500 | M25: 22500 | N25: 22500 | O25: 22500 | P25: 22500 | Q25: =SUMIF('Linked IS'!$B$3:$B$69,SOMCI!B25,'Linked IS'!$D$3:$D$69) -> 22500 | R25: =SUM(F25:Q25) -> 270000
B26: Machine Repair & Maintenance | F26: 241 | G26: 1567 | H26: 348 | I26: 292 | J26: 2106 | K26: 97 | L26: 2348 | M26: 0 | N26: 0 | O26: 0 | P26: 845 | Q26: =SUMIF('Linked IS'!$B$3:$B$69,SOMCI!B26,'Linked IS'!$D$3:$D$69) -> 0 | R26: =SUM(F26:Q26) -> 7844
B27: Vehicle Repairs and Maintenance | F27: 4554 | G27: 5564 | H27: 843 | I27: 4184 | J27: 479 | K27: 1901 | L27: 6883 | M27: 1279 | N27: 2362 | O27: 1300 | P27: 4267 | Q27: =SUMIF('Linked IS'!$B$3:$B$69,SOMCI!B27,'Linked IS'!$D$3:$D$69) -> 6950 | R27: =SUM(F27:Q27) -> 40566
B28: Rent Expense | F28: 0 | G28: 0 | H28: 0 | I28: 0 | J28: 0 | K28: 0 | L28: 0 | M28: 0 | N28: 0 | O28: 0 | P28: 0 | Q28: =SUMIF('Linked IS'!$B$3:$B$69,SOMCI!B28,'Linked IS'!$D$3:$D$69) -> 0 | R28: =SUM(F28:Q28) -> 0
B29: Fuel Expense | F29: 14451.54 | G29: 14077.8 | H29: 14587.23 | I29: 12979.2 | J29: 11703.78 | K29: 9017.28 | L29: 10134.53 | M29: 8189.65 | N29: 8074.43 | O29: 8785.32 | P29: 9645.67 | Q29: =SUMIF('Linked IS'!$B$3:$B$69,SOMCI!B29,'Linked IS'!$D$3:$D$69) -> 7143 | R29: =SUM(F29:Q29) -> 128789.43
B30: Freight And Delivery | F30: 0 | G30: 0 | H30: 0 | I30: 425 | J30: 50 | K30: 425 | L30: 0 | M30: 0 | N30: 0 | O30: 0 | P30: 0 | Q30: =SUMIF('Linked IS'!$B$3:$B$69,SOMCI!B30,'Linked IS'!$D$3:$D$69)+'Linked IS'!D52 -> 1100 | R30: =SUM(F30:Q30) -> 2000
A31: Administrative Exp. | F31: =SUM(F32:F54) -> 37773.87 | G31: =SUM(G32:G54) -> 37600.12 | H31: =SUM(H32:H54) -> 74053.09 | I31: =SUM(I32:I54) -> 37111.61 | J31: =SUM(J32:J54) -> 52715.72 | K31: =SUM(K32:K54) -> 33737.32 | L31: =SUM(L32:L54) -> 78737.52 | M31: =SUM(M32:M54) -> 35154.68 | ... Q31: =SUM(Q32:Q54) -> 43973.02 | R31: =SUM(F31:Q31) -> 582074.17
B32: Salaries and Wages | F32: 12134 | G32: 12984 | H32: 13682 | I32: 13500 | J32: 13400 | K32: 13900 | L32: 11400 | M32: 12850 | N32: 11766 | O32: 13850 | P32: 15016 | Q32: =SUMIF('Linked IS'!$B$3:$B$69,SOMCI!B32,'Linked IS'!$D$3:$D$69) -> 14100 | R32: =SUM(F32:Q32) -> 158582
B33: Travel & Transport | F33: 723 | G33: 0 | H33: 30 | I33: 0 | J33: 103 | K33: 45 | L33: 90 | M33: 45 | N33: 0 | O33: 0 | P33: 584 | Q33: =SUMIF('Linked IS'!$B$3:$B$69,SOMCI!B33,'Linked IS'!$D$3:$D$69) -> 0 | R33: =SUM(F33:Q33) -> 1620
B34: Office Repairs and Maintenance | F34: 0 | G34: 0 | H34: 0 | I34: 0 | J34: 0 | K34: 27 | L34: 0 | M34: 0 | N34: 0 | O34: 0 | P34: 0 | Q34: =SUMIF('Linked IS'!$B$3:$B$69,SOMCI!B34,'Linked IS'!$D$3:$D$69) -> 1200 | R34: =SUM(F34:Q34) -> 1227
B35: Meal And Entertainmnet | F35: 0 | G35: 0 | H35: 0 | I35: 0 | J35: 0 | K35: 0 | L35: 0 | M35: 0 | N35: 0 | O35: 0 | P35: 0 | Q35: =SUMIF('Linked IS'!$B$3:$B$69,SOMCI!B35,'Linked IS'!$D$3:$D$69) -> 0 | R35: =SUM(F35:Q35) -> 0
B36: Printing and Stationary | F36: 55 | G36: 0 | H36: 320 | I36: 320 | J36: 320 | K36: 390 | L36: 320 | M36: 365 | N36: 400 | O36: 0 | P36: 90 | Q36: =SUMIF('Linked IS'!$B$3:$B$69,SOMCI!B36,'Linked IS'!$D$3:$D$69) -> 0 | R36: =SUM(F36:Q36) -> 2580
B37: Utiliies Expense | F37: 976.08 | G37: 1288.03 | H37: 1349.84 | I37: 1305.59 | J37: 1528.97 | K37: 0 | L37: 703.78 | M37: 0 | N37: 2777.33 | O37: 0 | P37: 1377.88 | Q37: =SUMIF('Linked IS'!$B$3:$B$69,SOMCI!B37,'Linked IS'!$D$3:$D$69) -> 0 | R37: =SUM(F37:Q37) -> 11307.5
B38: Mobile & Communication | F38: 2315.25 | G38: 3666.84 | H38: 2350.71 | I38: 2327.41 | J38: 2316.29 | K38: 0 | L38: 2315.25 | M38: 0 | N38: 8933.91 | O38: 0 | P38: 4586.57 | Q38: =SUMIF('Linked IS'!$B$3:$B$69,SOMCI!B38,'Linked IS'!$D$3:$D$69) -> 0 | R38: =SUM(F38:Q38) -> 28812.23
B39: Office Supplies | F39: 200 | G39: 355 | H39: 450 | I39: 220 | J39: 437 | K39: 300 | L39: 200 | M39: 410 | N39: 200 | O39: 0 | P39: 610 | Q39: =SUMIF('Linked IS'!$B$3:$B$69,SOMCI!B39,'Linked IS'!$D$3:$D$69) -> 0 | R39: =SUM(F39:Q39) -> 3382
B40: Personal Expense Mr Saeed | F40: 0 | G40: 0 | H40: 0 | I40: 0 | J40: 0 | K40: 0 | L40: 0 | M40: 0 | N40: 0 | O40: 0 | P40: 1700 | Q40: =SUMIF('Linked IS'!$B$3:$B$69,SOMCI!B40,'Linked IS'!$D$3:$D$69) -> 200 | R40: =SUM(F40:Q40) -> 1900
B41: Rent Apartment & Store Exp. Abu Dhabi | F41: 3686.62 | G41: 3686.62 | H41: 3686.62 | I41: 3686.62 | J41: 3686.62 | K41: 3686.62 | L41: 3686.62 | M41: 3686.62 | N41: 3686.62 | O41: 3686.62 | P41: 3686.62 | Q41: =SUMIF('Linked IS'!$B$3:$B$69,SOMCI!B41,'Linked IS'!$D$3:$D$69) -> 3795 | R41: =SUM(F41:Q41) -> 44347.82
B42: Rent Apartment & Store Exp. Ajman | F42: 3243.87 | G42: 3274.58 | H42: 3302.3 | I42: 3289.94 | J42: 3258.35 | K42: 3776.15 | L42: 1723.63 | M42: 3989.15 | N42: 4404.93 | O42: 3989.15 | P42: 3989.15 | Q42: =SUMIF('Linked IS'!$B$3:$B$69,SOMCI!B42,'Linked IS'!$D$3:$D$69) -> 3989.15 | R42: =SUM(F42:Q42) -> 42230.35
